Workbook

Sheet Accueil
B2: RELÈVE CLASSEUR DE PILOTAGE PMO
B6: 1. Identité du projet
B7: Produit | C7: Relève | D7: InteriMatch est l'intitulé du sujet, Relève le nom du produit
B8: Secteur | C8: Aide à domicile | D8: Cible : SAAD prestataires autorisés, en B2B
B9: Groupe | C9: 5 | D9: Emma, Boubacar, Nina, Dirimo, Enzo
B10: Période | C10: 14 au 28/09/2026 | D10: 11 jours ouvrés
B11: Go/nogo | C11: 16/09/2026 | D11: Remise du cahier des charges
B12: Démonstration | C12: En local | D12: Pas de déploiement en ligne
B13: Responsable du classeur | C13: PMO | D13: Seul à saisir dans l'onglet Chiffrage
B15: 2. Capacité et occupation
B16: Méthode reprise du cahier des charges. Un jour-homme vaut une journée de présence. La journée réelle fait 6 h 15 (9h30-17h15, pause 12h30-14h00), et non 7 h.
B17: Poste | C17: Valeur | D17: Hypothèse
B18: Nombre de membres | C18: 5 | D18: Groupe complet
B19: Jours pleins par personne | C19: 10 | D19: Du 14 au 25 septembre
B20: Demi-journée du 28 septembre | C20: 0.5 | D20: Jour de soutenance
B21: Capacité totale (jours-homme) | C21: =C18*(C19+C20) -> 52.5 | D21: Membres × (jours pleins + demi-journée)
B22: Capacité totale (heures, à 6,25 h par jour) | C22: =C21*6.25 -> 328.125
B23: Total planifié (onglet Chiffrage) | C23: =IFERROR(Chiffrage!G53,0) -> 48
B24: Marge restante (jours-homme) | C24: =C21-C23 -> 4.5
B25: Taux d'occupation | C25: =IFERROR(C23/C21,0) -> 0.91428571
B26: VERDICT | C26: =IF(C23=0,"À chiffrer",IF(C25>0.9,"TROP TENDU",IF(C25>0.85,"Tenable, marge faible","Confortable"))) -> TROP TENDU
B28: 3. Charge par personne
B30: Membre | C30: Planifié (JH) | D30: Disponible (JH) | E30: Occupation
B31: Emma | C31: =SUMIF(Chiffrage!$E:$E,B31,Chiffrage!$G:$G) -> 8.25 | D31: =$C$19+$C$20 -> 10.5 | E31: =IFERROR(C31/D31,0) -> 0.78571429
B32: Nina | C32: =SUMIF(Chiffrage!$E:$E,B32,Chiffrage!$G:$G) -> 10.25 | D32: =$C$19+$C$20 -> 10.5 | E32: =IFERROR(C32/D32,0) -> 0.97619048
B33: Boubacar | C33: =SUMIF(Chiffrage!$E:$E,B33,Chiffrage!$G:$G) -> 10.5 | D33: =$C$19+$C$20 -> 10.5 | E33: =IFERROR(C33/D33,0) -> 1
B34: Enzo | C34: =SUMIF(Chiffrage!$E:$E,B34,Chiffrage!$G:$G) -> 9.25 | D34: =$C$19+$C$20 -> 10.5 | E34: =IFERROR(C34/D34,0) -> 0.88095238
B35: Dirimo | C35: =SUMIF(Chiffrage!$E:$E,B35,Chiffrage!$G:$G) -> 9.75 | D35: =$C$19+$C$20 -> 10.5 | E35: =IFERROR(C35/D35,0) -> 0.92857143
B37: Les prénoms doivent rester orthographiés à l'identique ici, dans la colonne Responsable du Chiffrage et dans le Suivi temps, sinon les cumuls renvoient zéro.

Sheet Chiffrage
A1: CHIFFRAGE DES TÂCHES
A3: Ne pas supprimer l'onglet Accueil : les lignes de capacité ci-dessous y puisent leurs valeurs.
A4: Bloc | B4: ID | C4: Tâche | D4: Exigé par le sujet | E4: Responsable | F4: Priorité | G4: Estim. (JH) | H4: Estim. (h) | I4: Réel (h) | J4: Écart (h) | K4: Écart (%) | L4: Statut | M4: Commentaire
A5: Cadrage et pilotage | B5: C01 | C5: Étude de marché | D5: Oui | E5: Emma | F5: Must have | G5: 1.5 | H5: =G5*6.25 -> 9.375 | I5: =SUMIF('Suivi temps'!$C:$C,B5,'Suivi temps'!$E:$E) -> 6.25 | J5: =IF(I5=0,0,I5-H5) -> -3.125 | K5: =IFERROR(J5/H5,0) -> -0.33333333 | L5: Fait
A6: Cadrage et pilotage | B6: C02 | C6: Analyse de marché et positionnement | D6: Oui | E6: Emma | F6: Must have | G6: 1 | H6: =G6*6.25 -> 6.25 | I6: =SUMIF('Suivi temps'!$C:$C,B6,'Suivi temps'!$E:$E) -> 6.25 | J6: =IF(I6=0,0,I6-H6) -> 0 | K6: =IFERROR(J6/H6,0) -> 0 | L6: Fait
A7: Cadrage et pilotage | B7: C03 | C7: Cahier des charges | D7: Oui | E7: Boubacar | F7: Must have | G7: 1.5 | H7: =G7*6.25 -> 9.375 | I7: =SUMIF('Suivi temps'!$C:$C,B7,'Suivi temps'!$E:$E) -> 6.25 | J7: =IF(I7=0,0,I7-H7) -> -3.125 | K7: =IFERROR(J7/H7,0) -> -0.33333333 | L7: Fait
A8: Cadrage et pilotage | B8: C04 | C8: Dérisquage des données publiques (test API) | D8: Oui | E8: Enzo | F8: Must have | G8: 0.75 | H8: =G8*6.25 -> 4.6875 | I8: =SUMIF('Suivi temps'!$C:$C,B8,'Suivi temps'!$E:$E) -> 6.25 | J8: =IF(I8=0,0,I8-H8) -> 1.5625 | K8: =IFERROR(J8/H8,0) -> 0.33333333 | L8: Fait
A9: Cadrage et pilotage | B9: C05 | C9: Entretien terrain avec une structure | D9: Non | E9: Nina | F9: Should have | G9: 0.75 | H9: =G9*6.25 -> 4.6875 | I9: =SUMIF('Suivi temps'!$C:$C,B9,'Suivi temps'!$E:$E) -> 6.25 | J9: =IF(I9=0,0,I9-H9) -> 1.5625 | K9: =IFERROR(J9/H9,0) -> 0.33333333 | L9: Fait
A10: Cadrage et pilotage | B10: C06 | C10: Pilotage, relevé du temps, points quotidiens | D10: Non | E10: Boubacar | F10: Must have | G10: 2.75 | H10: =G10*6.25 -> 17.1875 | I10: =SUMIF('Suivi temps'!$C:$C,B10,'Suivi temps'!$E:$E) -> 12.5 | J10: =IF(I10=0,0,I10-H10) -> -4.6875 | K10: =IFERROR(J10/H10,0) -> -0.27272727 | L10: En cours | M10: Tâche continue jusqu'à la soutenance.
A11: Socle technique | B11: S01 | C11: Dépôt, arborescence, README initial | D11: Oui | E11: Boubacar | F11: Must have | G11: 0.75 | H11: =G11*6.25 -> 4.6875 | I11: =SUMIF('Suivi temps'!$C:$C,B11,'Suivi temps'!$E:$E) -> 9.4 | J11: =IF(I11=0,0,I11-H11) -> 4.7125 | K11: =IFERROR(J11/H11,0) -> 1.0053333 | L11: Fait
A12: Socle technique | B12: S02 | C12: Environnement de développement et bases | D12: Oui | E12: Boubacar | F12: Must have | G12: 1.25 | H12: =G12*6.25 -> 7.8125 | I12: =SUMIF('Suivi temps'!$C:$C,B12,'Suivi temps'!$E:$E) -> 9.35 | J12: =IF(I12=0,0,I12-H12) -> 1.5375 | K12: =IFERROR(J12/H12,0) -> 0.1968 | L12: Fait
A13: Socle technique | B13: S03 | C13: Intégration continue | D13: Non | E13: Boubacar | F13: Should have | G13: 0.75 | H13: =G13*6.25 -> 4.6875 | I13: =SUMIF('Suivi temps'!$C:$C,B13,'Suivi temps'!$E:$E) -> 6.25 | J13: =IF(I13=0,0,I13-H13) -> 1.5625 | K13: =IFERROR(J13/H13,0) -> 0.33333333 | L13: Fait
A14: Socle technique | B14: S04 | C14: Maquettes des écrans | D14: Non | E14: Nina | F14: Should have | G14: 1 | H14: =G14*6.25 -> 6.25 | I14: =SUMIF('Suivi temps'!$C:$C,B14,'Suivi temps'!$E:$E) -> 9.4 | J14: =IF(I14=0,0,I14-H14) -> 3.15 | K14: =IFERROR(J14/H14,0) -> 0.504 | L14: Fait
A15: Comptes et sécurité | B15: A01 | C15: Inscription et parcours structure | D15: Oui | E15: Nina | F15: Must have | G15: 0.75 | H15: =G15*6.25 -> 4.6875 | I15: =SUMIF('Suivi temps'!$C:$C,B15,'Suivi temps'!$E:$E) -> 6.25 | J15: =IF(I15=0,0,I15-H15) -> 1.5625 | K15: =IFERROR(J15/H15,0) -> 0.33333333 | L15: Fait
A16: Comptes et sécurité | B16: A02 | C16: Inscription et parcours intervenant | D16: Oui | E16: Nina | F16: Must have | G16: 0.75 | H16: =G16*6.25 -> 4.6875 | I16: =SUMIF('Suivi temps'!$C:$C,B16,'Suivi temps'!$E:$E) -> 6.25 | J16: =IF(I16=0,0,I16-H16) -> 1.5625 | K16: =IFERROR(J16/H16,0) -> 0.33333333 | L16: Fait
A17: Comptes et sécurité | B17: A03 | C17: Authentification développée par nous | D17: Oui | E17: Dirimo | F17: Must have | G17: 1.25 | H17: =G17*6.25 -> 7.8125 | I17: =SUMIF('Suivi temps'!$C:$C,B17,'Suivi temps'!$E:$E) -> 12.5 | J17: =IF(I17=0,0,I17-H17) -> 4.6875 | K17: =IFERROR(J17/H17,0) -> 0.6 | L17: Fait | M17: Terminé le 18/09. Dépassement lié à la prise en main des jetons et du renouvellement de session.
A18: Comptes et sécurité | B18: A04 | C18: Permissions par rôle | D18: Oui | E18: Dirimo | F18: Must have | G18: 0.5 | H18: =G18*6.25 -> 3.125 | I18: =SUMIF('Suivi temps'!$C:$C,B18,'Suivi temps'!$E:$E) -> 2.1 | J18: =IF(I18=0,0,I18-H18) -> -1.025 | K18: =IFERROR(J18/H18,0) -> -0.328 | L18: Fait
A19: Comptes et sécurité | B19: A05 | C19: Chiffrement des documents sensibles | D19: Oui | E19: Dirimo | F19: Must have | G19: 0.5 | H19: =G19*6.25 -> 3.125 | I19: =SUMIF('Suivi temps'!$C:$C,B19,'Suivi temps'!$E:$E) -> 6.25 | J19: =IF(I19=0,0,I19-H19) -> 3.125 | K19: =IFERROR(J19/H19,0) -> 1 | L19: Fait | M19: Dépassement à surveiller, non terminé au 18/09.
A20: Métier | B20: M01 | C20: Profil intervenant détaillé | D20: Oui | E20: Nina | F20: Must have | G20: 1.5 | H20: =G20*6.25 -> 9.375 | I20: =SUMIF('Suivi temps'!$C:$C,B20,'Suivi temps'!$E:$E) -> 6.25 | J20: =IF(I20=0,0,I20-H20) -> -3.125 | K20: =IFERROR(J20/H20,0) -> -0.33333333 | L20: Fait
A21: Métier | B21: M02 | C21: Dépôt d'un besoin par la structure | D21: Oui | E21: Emma | F21: Must have | G21: 1.5 | H21: =G21*6.25 -> 9.375 | I21: =SUMIF('Suivi temps'!$C:$C,B21,'Suivi temps'!$E:$E) -> 6.25 | J21: =IF(I21=0,0,I21-H21) -> -3.125 | K21: =IFERROR(J21/H21,0) -> -0.33333333 | L21: Fait
A22: Métier | B22: M03 | C22: Cycle de vie du besoin et historique daté | D22: Oui | E22: Dirimo | F22: Must have | G22: 1.75 | H22: =G22*6.25 -> 10.9375 | I22: =SUMIF('Suivi temps'!$C:$C,B22,'Suivi temps'!$E:$E) -> 6.25 | J22: =IF(I22=0,0,I22-H22) -> -4.6875 | K22: =IFERROR(J22/H22,0) -> -0.42857143 | L22: Fait
A23: Métier | B23: M04 | C23: Tableau de bord des états | D23: Oui | E23: Nina | F23: Must have | G23: 1.25 | H23: =G23*6.25 -> 7.8125 | I23: =SUMIF('Suivi temps'!$C:$C,B23,'Suivi temps'!$E:$E) -> 3.15 | J23: =IF(I23=0,0,I23-H23) -> -4.6625 | K23: =IFERROR(J23/H23,0) -> -0.5968 | L23: Fait
A24: Métier | B24: M05 | C24: Pages publiques d'annonces | D24: Oui | E24: Nina | F24: Must have | G24: 0.75 | H24: =G24*6.25 -> 4.6875 | I24: =SUMIF('Suivi temps'!$C:$C,B24,'Suivi temps'!$E:$E) -> 3.1 | J24: =IF(I24=0,0,I24-H24) -> -1.5875 | K24: =IFERROR(J24/H24,0) -> -0.33866667 | L24: Fait
A25: Matching | B25: X01 | C25: Filtres éliminatoires dont contrôle Valletoux | D25: Oui | E25: Dirimo | F25: Must have | G25: 1.25 | H25: =G25*6.25 -> 7.8125 | I25: =SUMIF('Suivi temps'!$C:$C,B25,'Suivi temps'!$E:$E) -> 6.25 | J25: =IF(I25=0,0,I25-H25) -> -1.5625 | K25: =IFERROR(J25/H25,0) -> -0.2 | L25: Fait
A26: Matching | B26: X02 | C26: Score pondéré compétences, zone, créneaux | D26: Oui | E26: Dirimo | F26: Must have | G26: 1.5 | H26: =G26*6.25 -> 9.375 | I26: =SUMIF('Suivi temps'!$C:$C,B26,'Suivi temps'!$E:$E) -> 4.15 | J26: =IF(I26=0,0,I26-H26) -> -5.225 | K26: =IFERROR(J26/H26,0) -> -0.55733333 | L26: Fait
A27: Matching | B27: X03 | C27: Short-list, acceptation, refus motivé | D27: Oui | E27: Dirimo | F27: Must have | G27: 0.75 | H27: =G27*6.25 -> 4.6875 | I27: =SUMIF('Suivi temps'!$C:$C,B27,'Suivi temps'!$E:$E) -> 3.15 | J27: =IF(I27=0,0,I27-H27) -> -1.5375 | K27: =IFERROR(J27/H27,0) -> -0.328 | L27: Fait
A28: Matching | B28: X04 | C28: Journal des décisions de matching | D28: Oui | E28: Dirimo | F28: Must have | G28: 0.5 | H28: =G28*6.25 -> 3.125 | I28: =SUMIF('Suivi temps'!$C:$C,B28,'Suivi temps'!$E:$E) -> 3.1 | J28: =IF(I28=0,0,I28-H28) -> -0.025 | K28: =IFERROR(J28/H28,0) -> -0.008 | L28: Fait
A29: Données publiques | B29: D01 | C29: Import API France Travail en ligne de commande | D29: Oui | E29: Enzo | F29: Must have | G29: 1.25 | H29: =G29*6.25 -> 7.8125 | I29: =SUMIF('Suivi temps'!$C:$C,B29,'Suivi temps'!$E:$E) -> 6.25 | J29: =IF(I29=0,0,I29-H29) -> -1.5625 | K29: =IFERROR(J29/H29,0) -> -0.2 | L29: Fait
A30: Données publiques | B30: D02 | C30: Nettoyage, normalisation, dédoublonnage | D30: Oui | E30: Enzo | F30: Must have | G30: 1.25 | H30: =G30*6.25 -> 7.8125 | I30: =SUMIF('Suivi temps'!$C:$C,B30,'Suivi temps'!$E:$E) -> 6.25 | J30: =IF(I30=0,0,I30-H30) -> -1.5625 | K30: =IFERROR(J30/H30,0) -> -0.2 | L30: Fait
A31: Données publiques | B31: D03 | C31: Indicateur de tension affiché à la saisie | D31: Oui | E31: Enzo | F31: Must have | G31: 1 | H31: =G31*6.25 -> 6.25 | I31: =SUMIF('Suivi temps'!$C:$C,B31,'Suivi temps'!$E:$E) -> 6.25 | J31: =IF(I31=0,0,I31-H31) -> 0 | K31: =IFERROR(J31/H31,0) -> 0 | L31: Fait
A32: Données publiques | B32: D04 | C32: Jeu de données de démonstration | D32: Non | E32: Enzo | F32: Must have | G32: 0.5 | H32: =G32*6.25 -> 3.125 | I32: =SUMIF('Suivi temps'!$C:$C,B32,'Suivi temps'!$E:$E) -> 6.25 | J32: =IF(I32=0,0,I32-H32) -> 3.125 | K32: =IFERROR(J32/H32,0) -> 1 | L32: Fait | M32: olume de données à générer plus important que prévu.
A33: Automatisations | B33: N01 | C33: Notification automatique aux profils retenus | D33: Oui | E33: Enzo | F33: Must have | G33: 1.5 | H33: =G33*6.25 -> 9.375 | I33: =SUMIF('Suivi temps'!$C:$C,B33,'Suivi temps'!$E:$E) -> 3.15 | J33: =IF(I33=0,0,I33-H33) -> -6.225 | K33: =IFERROR(J33/H33,0) -> -0.664 | L33: Fait
A34: Automatisations | B34: N02 | C34: Relance automatique des besoins non pourvus | D34: Oui | E34: Enzo | F34: Must have | G34: 1.25 | H34: =G34*6.25 -> 7.8125 | I34: =SUMIF('Suivi temps'!$C:$C,B34,'Suivi temps'!$E:$E) -> 3.1 | J34: =IF(I34=0,0,I34-H34) -> -4.7125 | K34: =IFERROR(J34/H34,0) -> -0.6032 | L34: Fait
A35: Automatisations | B35: N03 | C35: Base tampon et exports des scénarios | D35: Oui | E35: Enzo | F35: Must have | G35: 0.75 | H35: =G35*6.25 -> 4.6875 | I35: =SUMIF('Suivi temps'!$C:$C,B35,'Suivi temps'!$E:$E) -> 3.15 | J35: =IF(I35=0,0,I35-H35) -> -1.5375 | K35: =IFERROR(J35/H35,0) -> -0.328 | L35: Fait
A36: Conformité | B36: K01 | C36: RGPD : base légale, conservation, mentions | D36: Oui | E36: Emma | F36: Must have | G36: 1 | H36: =G36*6.25 -> 6.25 | I36: =SUMIF('Suivi temps'!$C:$C,B36,'Suivi temps'!$E:$E) -> 6.25 | J36: =IF(I36=0,0,I36-H36) -> 0 | K36: =IFERROR(J36/H36,0) -> 0 | L36: Fait
A37: Conformité | B37: K02 | C37: Code du travail : mentions du contrat, durée maximale | D37: Oui | E37: Emma | F37: Must have | G37: 1.25 | H37: =G37*6.25 -> 7.8125 | I37: =SUMIF('Suivi temps'!$C:$C,B37,'Suivi temps'!$E:$E) -> 12.5 | J37: =IF(I37=0,0,I37-H37) -> 4.6875 | K37: =IFERROR(J37/H37,0) -> 0.6 | L37: Fait
A38: Conformité | B38: K03 | C38: Accessibilité RGAA 4.1 | D38: Oui | E38: Emma | F38: Must have | G38: 1 | H38: =G38*6.25 -> 6.25 | I38: =SUMIF('Suivi temps'!$C:$C,B38,'Suivi temps'!$E:$E) -> 6.25 | J38: =IF(I38=0,0,I38-H38) -> 0 | K38: =IFERROR(J38/H38,0) -> 0 | L38: Fait
A39: Conformité | B39: K04 | C39: Éco-conception RGESN, mesure avant et après | D39: Oui | E39: Enzo | F39: Must have | G39: 1 | H39: =G39*6.25 -> 6.25 | I39: =SUMIF('Suivi temps'!$C:$C,B39,'Suivi temps'!$E:$E) -> 3.1 | J39: =IF(I39=0,0,I39-H39) -> -3.15 | K39: =IFERROR(J39/H39,0) -> -0.504 | L39: Fait
A40: Conformité | B40: K05 | C40: Référencement : balises, titres, sitemap | D40: Oui | E40: Nina | F40: Must have | G40: 1 | H40: =G40*6.25 -> 6.25 | I40: =SUMIF('Suivi temps'!$C:$C,B40,'Suivi temps'!$E:$E) -> 3.1 | J40: =IF(I40=0,0,I40-H40) -> -3.15 | K40: =IFERROR(J40/H40,0) -> -0.504 | L40: Fait
A41: Qualité et recette | B41: Q01 | C41: Tests unitaires | D41: Oui | E41: Dirimo | F41: Must have | G41: 1.75 | H41: =G41*6.25 -> 10.9375 | I41: =SUMIF('Suivi temps'!$C:$C,B41,'Suivi temps'!$E:$E) -> 15.65 | J41: =IF(I41=0,0,I41-H41) -> 4.7125 | K41: =IFERROR(J41/H41,0) -> 0.43085714 | L41: Fait
...

Sheet Suivi temps
A1: SUIVI DU TEMPS PASSÉ
A2: Une ligne par personne, par jour et par tâche. La semaine du 14 au 18 septembre est pré-remplie en dates, prénoms et heures : il reste à saisir l'ID de tâche en colonne C.
A4: Date | B4: Membre | C4: ID tâche | D4: Tâche (automatique) | E4: Heures | F4: Commentaire | H4: Cumul par membre
A5: 14/09/2026 | B5: Emma | C5: C01 | D5: =IFERROR(INDEX(Chiffrage!$C:$C,MATCH(C5,Chiffrage!$B:$B,0)),"") -> Étude de marché | E5: 6.25 | H5: Membre | I5: Heures | J5: Jours-homme
A6: 14/09/2026 | B6: Nina | C6: C05 | D6: =IFERROR(INDEX(Chiffrage!$C:$C,MATCH(C6,Chiffrage!$B:$B,0)),"") -> Entretien terrain avec une structure | E6: 6.25 | H6: Emma | I6: =SUMIF($B:$B,H6,$E:$E) -> 56.25 | J6: =I6/6.25 -> 9
A7: 14/09/2026 | B7: Boubacar | C7: C03 | D7: =IFERROR(INDEX(Chiffrage!$C:$C,MATCH(C7,Chiffrage!$B:$B,0)),"") -> Cahier des charges | E7: 6.25 | H7: Nina | I7: =SUMIF($B:$B,H7,$E:$E) -> 56.25 | J7: =I7/6.25 -> 9
A8: 14/09/2026 | B8: Enzo | C8: C04 | D8: =IFERROR(INDEX(Chiffrage!$C:$C,MATCH(C8,Chiffrage!$B:$B,0)),"") -> Dérisquage des données publiques (test API) | E8: 6.25 | H8: Boubacar | I8: =SUMIF($B:$B,H8,$E:$E) -> 56.25 | J8: =I8/6.25 -> 9
A9: 14/09/2026 | B9: Dirimo | C9: A03 | D9: =IFERROR(INDEX(Chiffrage!$C:$C,MATCH(C9,Chiffrage!$B:$B,0)),"") -> Authentification développée par nous | E9: 6.25 | H9: Enzo | I9: =SUMIF($B:$B,H9,$E:$E) -> 56.25 | J9: =I9/6.25 -> 9
A10: 15/09/2026 | B10: Emma | C10: C02 | D10: =IFERROR(INDEX(Chiffrage!$C:$C,MATCH(C10,Chiffrage!$B:$B,0)),"") -> Analyse de marché et positionnement | E10: 6.25 | H10: Dirimo | I10: =SUMIF($B:$B,H10,$E:$E) -> 56.25 | J10: =I10/6.25 -> 9
A11: 15/09/2026 | B11: Nina | C11: S04 | D11: =IFERROR(INDEX(Chiffrage!$C:$C,MATCH(C11,Chiffrage!$B:$B,0)),"") -> Maquettes des écrans | E11: 6.25 | H11: TOTAL | I11: =SUM(I6:I10) -> 281.25 | J11: =SUM(J6:J10) -> 45
A12: 15/09/2026 | B12: Boubacar | C12: C06 | D12: =IFERROR(INDEX(Chiffrage!$C:$C,MATCH(C12,Chiffrage!$B:$B,0)),"") -> Pilotage, relevé du temps, points quotidiens | E12: 6.25
A13: 15/09/2026 | B13: Enzo | C13: D01 | D13: =IFERROR(INDEX(Chiffrage!$C:$C,MATCH(C13,Chiffrage!$B:$B,0)),"") -> Import API France Travail en ligne de commande | E13: 6.25
A14: 15/09/2026 | B14: Dirimo | C14: A03 | D14: =IFERROR(INDEX(Chiffrage!$C:$C,MATCH(C14,Chiffrage!$B:$B,0)),"") -> Authentification développée par nous | E14: 6.25
A15: 16/09/2026 | B15: Emma | C15: M02 | D15: =IFERROR(INDEX(Chiffrage!$C:$C,MATCH(C15,Chiffrage!$B:$B,0)),"") -> Dépôt d'un besoin par la structure | E15: 6.25
A16: 16/09/2026 | B16: Nina | C16: A01 | D16: =IFERROR(INDEX(Chiffrage!$C:$C,MATCH(C16,Chiffrage!$B:$B,0)),"") -> Inscription et parcours structure | E16: 6.25
A17: 16/09/2026 | B17: Boubacar | C17: S01 | D17: =IFERROR(INDEX(Chiffrage!$C:$C,MATCH(C17,Chiffrage!$B:$B,0)),"") -> Dépôt, arborescence, README initial | E17: 6.25
A18: 16/09/2026 | B18: Enzo | C18: D02 | D18: =IFERROR(INDEX(Chiffrage!$C:$C,MATCH(C18,Chiffrage!$B:$B,0)),"") -> Nettoyage, normalisation, dédoublonnage | E18: 6.25
A19: 16/09/2026 | B19: Dirimo | C19: A05 | D19: =IFERROR(INDEX(Chiffrage!$C:$C,MATCH(C19,Chiffrage!$B:$B,0)),"") -> Chiffrement des documents sensibles | E19: 6.25
A20: 17/09/2026 | B20: Emma | C20: K01 | D20: =IFERROR(INDEX(Chiffrage!$C:$C,MATCH(C20,Chiffrage!$B:$B,0)),"") -> RGPD : base légale, conservation, mentions | E20: 6.25
A21: 17/09/2026 | B21: Nina | C21: A02 | D21: =IFERROR(INDEX(Chiffrage!$C:$C,MATCH(C21,Chiffrage!$B:$B,0)),"") -> Inscription et parcours intervenant | E21: 6.25
A22: 17/09/2026 | B22: Boubacar | C22: S02 | D22: =IFERROR(INDEX(Chiffrage!$C:$C,MATCH(C22,Chiffrage!$B:$B,0)),"") -> Environnement de développement et bases | E22: 6.25
A23: 17/09/2026 | B23: Enzo | C23: D03 | D23: =IFERROR(INDEX(Chiffrage!$C:$C,MATCH(C23,Chiffrage!$B:$B,0)),"") -> Indicateur de tension affiché à la saisie | E23: 6.25
... A38: 21/09/2026 | B38: Enzo | C38: N02 | D38: =IFERROR(INDEX(Chiffrage!$C:$C,MATCH(C38,Chiffrage!$B:$B,0)),"") -> Relance automatique des besoins non pourvus | E38: 3.1
A39: 22/09/2026 | B39: Emma | C39: K02 | D39: =IFERROR(INDEX(Chiffrage!$C:$C,MATCH(C39,Chiffrage!$B:$B,0)),"") -> Code du travail : mentions du contrat, durée maximale | E39: 6.25 | F39: Relecture des documents réglementaires
A40: 22/09/2026 | B40: Nina | C40: S04 | D40: =IFERROR(INDEX(Chiffrage!$C:$C,MATCH(C40,Chiffrage!$B:$B,0)),"") -> Maquettes des écrans | E40: 3.15 | F40: Maquette
A41: 22/09/2026 | B41: Nina | C41: K05 | D41: =IFERROR(INDEX(Chiffrage!$C:$C,MATCH(C41,Chiffrage!$B:$B,0)),"") -> Référencement : balises, titres, sitemap | E41: 3.1 | F41: Référencement
A42: 22/09/2026 | B42: Boubacar | C42: C06 | D42: =IFERROR(INDEX(Chiffrage!$C:$C,MATCH(C42,Chiffrage!$B:$B,0)),"") -> Pilotage, relevé du temps, points quotidiens | E42: 6.25 | F42: Relecture et second follow-up
A43: 22/09/2026 | B43: Dirimo | C43: X03 | D43: =IFERROR(INDEX(Chiffrage!$C:$C,MATCH(C43,Chiffrage!$B:$B,0)),"") -> Short-list, acceptation, refus motivé | E43: 3.15 | F43: Mise au point de la démo
A44: 22/09/2026 | B44: Dirimo | C44: X04 | D44: =IFERROR(INDEX(Chiffrage!$C:$C,MATCH(C44,Chiffrage!$B:$B,0)),"") -> Journal des décisions de matching | E44: 3.1 | F44: Mise au point de la démo
A45: 22/09/2026 | B45: Enzo | C45: N03 | D45: =IFERROR(INDEX(Chiffrage!$C:$C,MATCH(C45,Chiffrage!$B:$B,0)),"") -> Base tampon et exports des scénarios | E45: 3.15 | F45: Vérification des automatisations
A46: 22/09/2026 | B46: Enzo | C46: K04 | D46: =IFERROR(INDEX(Chiffrage!$C:$C,MATCH(C46,Chiffrage!$B:$B,0)),"") -> Éco-conception RGESN, mesure avant et après | E46: 3.1
A47: 23/09/2026 | B47: Emma | C47: Q04 | E47: 6.25 | F47: Recette des critères d'acceptation
A48: 23/09/2026 | B48: Nina | C48: L03 | E48: 6.25 | F48: Support de pitch
A49: 23/09/2026 | B49: Boubacar | C49: Q02 | E49: 6.25 | F49: Tests fonctionnels des parcours critiques
A50: 23/09/2026 | B50: Enzo | C50: Q01 | E50: 6.25 | F50: Renfort sur les tests unitaires
A51: 23/09/2026 | B51: Dirimo | C51: Q01 | E51: 6.25 | F51: Tests unitaires
A52: 24/09/2026 | B52: Emma | C52: Q04 | E52: 3.15
A53: 24/09/2026 | B53: Emma | C53: L04 | E53: 3.1 | F53: Première répétition
A54: 24/09/2026 | B54: Nina | C54: L03 | E54: 3.15
A55: 24/09/2026 | B55: Nina | C55: L04 | E55: 3.1 | F55: Première répétition
...

Sheet Jalons
A1: JALONS ET PORTES DE SORTIE
A2: Repris du cahier des charges. Coche le passage le soir même, pas le lendemain.
A4: Jalon | B4: Date | C4: Ce qui doit être vrai | D4: Si ce n'est pas vrai | E4: Passé ? | F4: Constat
A5: M0 | B5: J1 · 14/09 | C5: Premier appel à l'API France Travail réussi, volumes comptés, département du POC choisi | D5: Repli sur un fichier téléchargé, indicateur réduit | E5: Oui | F5: API France Travail opérationnelle, volumes comptés
A6: M1 | B6: J2 · 15/09 | C6: Cahier des charges validé par les cinq, environnement de développement qui démarre | D6: Le PMO arbitre le soir même | E6: Oui | F6: Cahier des charges validé, environnement fonctionnel
A7: M2 | B7: J3 · 16/09 | C7: Point go/nogo : périmètre validé, coupes éventuelles actées | D7: — | E7: Oui | F7: Go/nogo tenu, périmètre validé sans coupe
A8: M3 | B8: J5 · 18/09 | C8: Comptes, permissions, documents chiffrés, profil, import de données qui tourne | D8: On coupe les deux optionnelles les moins visibles | E8: Oui | F8: Comptes, permissions, chiffrement, profil et import de données livrés
A9: M4 | B9: J8 · 23/09 | C9: Parcours complet joué en démo interne, de l'inscription à la validation | D9: On coupe le reste des optionnelles et on renforce le développement | E9: Oui | F9: Parcours complet fonctionnel de l'inscription à la validation
A10: M5 | B10: J8 · 23/09 | C10: Gel du code. Plus aucune nouvelle fonctionnalité, conformité terminée | D10: Ce qui n'est pas intégré sort du périmètre | E10: Oui | F10: Gel du code tenu. Périmètre livré, plus aucune nouvelle fonctionnalité.
A11: M6 | B11: J9 · 24/09 | C11: Couverture de tests générée, parcours critiques au vert, première répétition | D11: Plan B en captures et vidéo | E11: Oui | F11: Couverture de tests générée, parcours critiques au vert, première répétition faite.
A12: M7 | B12: J10 · 25/09 | C12: Écart estimé/réel produit, deuxième répétition, soutenance | D12: — | E12: Non | F12: Seconde répétition et soutenance.

Sheet Coupes
A1: ORDRE DE COUPE
A2: Décidé à froid. Dès qu'une tâche prend une demi-journée de retard, on coupe dans cet ordre, sans nouvelle discussion.
A4: Rang | B4: Ce qu'on coupe | C4: Gain estimé (JH) | D4: Coupé ? | E4: Date | F4: Décidé par
A5: 1 | B5: La confirmation de mission générée automatiquement | D5: Oui | E5: 23/09/2026 | F5: Groupe
A6: 2 | B6: L'autocomplétion des intitulés de poste | D6: Oui | E6: 23/09/2026 | F6: Groupe
A7: 3 | B7: Le tableau de suivi des notifications | D7: Oui | E7: 23/09/2026 | F7: Groupe
A8: 4 | B8: Relance manuelle plutôt qu'automatique après un refus | D8: Non
A9: 5 | B9: Liste sans pagination | D9: Non
A10: 6 | B10: Un seul type de document chiffré | D10: Non
B12: Ce que nous ne couperons jamais
B13: L'authentification
B14: Le cycle de vie du besoin
B15: Le contrôle légal Valletoux
B16: Le matching et son journal
B17: Les deux automatisations
B18: L'indicateur de tension
B19: Les tests et le rapport de couverture
B20: La conformité

Sheet Roadmap
A1: RELÈVE, Roadmap fonctionnelle
B3: 1. Priorisation : Maintenant, Ensuite, Plus tard
B4: Maintenant | E4: Ensuite | H4: Plus tard
B5: Cœur : comptes et sécurité, métier, matching | E5: Données publiques, automatisations, conformité, qualité | H5: Fonctionnalités optionnelles
B6: =Chiffrage!B15&" "&Chiffrage!C15 -> A01 Inscription et parcours structure | E6: =Chiffrage!B29&" "&Chiffrage!C29 -> D01 Import API France Travail en ligne de commande | H6: =Chiffrage!B49&" "&Chiffrage!C49 -> O01 Confirmation de mission générée depuis un modèle
B7: =Chiffrage!B16&" "&Chiffrage!C16 -> A02 Inscription et parcours intervenant | E7: =Chiffrage!B30&" "&Chiffrage!C30 -> D02 Nettoyage, normalisation, dédoublonnage | H7: =Chiffrage!B50&" "&Chiffrage!C50 -> O02 Autocomplétion des intitulés de poste
B8: =Chiffrage!B17&" "&Chiffrage!C17 -> A03 Authentification développée par nous | E8: =Chiffrage!B31&" "&Chiffrage!C31 -> D03 Indicateur de tension affiché à la saisie | H8: =Chiffrage!B51&" "&Chiffrage!C51 -> O03 Tableau de suivi des notifications et des délais
B9: =Chiffrage!B18&" "&Chiffrage!C18 -> A04 Permissions par rôle | E9: =Chiffrage!B32&" "&Chiffrage!C32 -> D04 Jeu de données de démonstration
B10: =Chiffrage!B19&" "&Chiffrage!C19 -> A05 Chiffrement des documents sensibles | E10: =Chiffrage!B33&" "&Chiffrage!C33 -> N01 Notification automatique aux profils retenus
B11: =Chiffrage!B20&" "&Chiffrage!C20 -> M01 Profil intervenant détaillé | E11: =Chiffrage!B34&" "&Chiffrage!C34 -> N02 Relance automatique des besoins non pourvus
B12: =Chiffrage!B21&" "&Chiffrage!C21 -> M02 Dépôt d'un besoin par la structure | E12: =Chiffrage!B35&" "&Chiffrage!C35 -> N03 Base tampon et exports des scénarios
B13: =Chiffrage!B22&" "&Chiffrage!C22 -> M03 Cycle de vie du besoin et historique daté | E13: =Chiffrage!B36&" "&Chiffrage!C36 -> K01 RGPD : base légale, conservation, mentions
B14: =Chiffrage!B23&" "&Chiffrage!C23 -> M04 Tableau de bord des états | E14: =Chiffrage!B37&" "&Chiffrage!C37 -> K02 Code du travail : mentions du contrat, durée maximale
B15: =Chiffrage!B24&" "&Chiffrage!C24 -> M05 Pages publiques d'annonces | E15: =Chiffrage!B38&" "&Chiffrage!C38 -> K03 Accessibilité RGAA 4.1
B16: =Chiffrage!B25&" "&Chiffrage!C25 -> X01 Filtres éliminatoires dont contrôle Valletoux | E16: =Chiffrage!B39&" "&Chiffrage!C39 -> K04 Éco-conception RGESN, mesure avant et après
B17: =Chiffrage!B26&" "&Chiffrage!C26 -> X02 Score pondéré compétences, zone, créneaux | E17: =Chiffrage!B40&" "&Chiffrage!C40 -> K05 Référencement : balises, titres, sitemap
B18: =Chiffrage!B27&" "&Chiffrage!C27 -> X03 Short-list, acceptation, refus motivé | E18: =Chiffrage!B41&" "&Chiffrage!C41 -> Q01 Tests unitaires
B19: =Chiffrage!B28&" "&Chiffrage!C28 -> X04 Journal des décisions de matching | E19: =Chiffrage!B42&" "&Chiffrage!C42 -> Q02 Tests fonctionnels des parcours critiques
E20: =Chiffrage!B43&" "&Chiffrage!C43 -> Q03 Rapport de couverture
E21: =Chiffrage!B44&" "&Chiffrage!C44 -> Q04 Recette des critères d'acceptation
B23: 2. Jalons M0 à M7
B24: Jalon | C24: Date | D24: Critère de passage
B25: =Jalons!A5 -> M0 | C25: =Jalons!B5 -> J1 · 14/09 | D25: =Jalons!C5 -> Premier appel à l'API France Travail réussi, volumes comptés, département du POC choisi
B26: =Jalons!A6 -> M1 | C26: =Jalons!B6 -> J2 · 15/09 | D26: =Jalons!C6 -> Cahier des charges validé par les cinq, environnement de développement qui démarre
B27: =Jalons!A7 -> M2 | C27: =Jalons!B7 -> J3 · 16/09 | D27: =Jalons!C7 -> Point go/nogo : périmètre validé, coupes éventuelles actées
B28: =Jalons!A8 -> M3 | C28: =Jalons!B8 -> J5 · 18/09 | D28: =Jalons!C8 -> Comptes, permissions, documents chiffrés, profil, import de données qui tourne
B29: =Jalons!A9 -> M4 | C29: =Jalons!B9 -> J8 · 23/09 | D29: =Jalons!C9 -> Parcours complet joué en démo interne, de l'inscription à la validation
B30: =Jalons!A10 -> M5 | C30: =Jalons!B10 -> J8 · 23/09 | D30: =Jalons!C10 -> Gel du code. Plus aucune nouvelle fonctionnalité, conformité terminée
B31: =Jalons!A11 -> M6 | C31: =Jalons!B11 -> J9 · 24/09 | D31: =Jalons!C11 -> Couverture de tests générée, parcours critiques au vert, première répétition
B32: =Jalons!A12 -> M7 | C32: =Jalons!B12 -> J10 · 25/09 | D32: =Jalons!C12 -> Écart estimé/réel produit, deuxième répétition, soutenance
